// 这无法使用：
const fs = require('fs');

//try {
    fs.readFile('/some/file/that/does-not-exist', (err, data) => {
        // 假设的错误：在这里抛出
        if (err) {
            throw err;
        }
    });
//} catch(err) {
    // 这不会捕获到抛出！,因为回调函数是异步的
    /*这无法使用，因为传给 fs.readFile() 的回调函数是被异步地调用。
    当回调被调用时，周围的代码（包括 try { } catch(err) { } 区域）已经退出。
    大多数情况下，在回调内抛出一个错误会使 Node.js 进程崩溃。
    如果域已启用，或已在 process.on('uncaughtException') 注册了一个句柄，则这些错误可被捕获。*/
  //  console.log(err);
//}
//注册了 process.on('uncaughtException') ，则这些错误可被捕获。
process.on("uncaughtException",function (err) {
    console.log(err);
})

console.log("hhe");